INFO:uvicorn.error:Started server process [9780]
INFO:uvicorn.error:Waiting for application startup.
INFO:uvicorn.error:Application startup complete.
INFO:uvicorn.error:Started server process [16476]
INFO:uvicorn.error:Waiting for application startup.
INFO:uvicorn.error:Application startup complete.
INFO:uvicorn.error:Started server process [20452]
INFO:uvicorn.error:Waiting for application startup.
INFO:uvicorn.error:Application startup complete.
INFO:uvicorn.error:Shutting down
INFO:uvicorn.error:Started server process [24960]
INFO:uvicorn.error:Waiting for application startup.
INFO:uvicorn.error:Application startup complete.
INFO:uvicorn.error:Started server process [11240]
INFO:uvicorn.error:Waiting for application startup.
INFO:uvicorn.error:Application startup complete.
INFO:uvicorn.error:Shutting down
INFO:uvicorn.error:Waiting for application shutdown.
INFO:uvicorn.error:Application shutdown complete.
INFO:uvicorn.error:Finished server process [11240]
INFO:uvicorn.error:Started server process [16764]
INFO:uvicorn.error:Waiting for application startup.
INFO:uvicorn.error:Application startup complete.
ERROR:uvicorn.error:Exception in ASGI application
Traceback (most recent call last):
  File "D:\2. Information Technology\15. Python\7. Learn\3. FastAPi\Example 1\venv\lib\site-packages\sqlalchemy\engine\base.py", line 3250, in _wrap_pool_connect
    return fn()
  File "D:\2. Information Technology\15. Python\7. Learn\3. FastAPi\Example 1\venv\lib\site-packages\sqlalchemy\pool\base.py", line 310, in connect
    return _ConnectionFairy._checkout(self)
  File "D:\2. Information Technology\15. Python\7. Learn\3. FastAPi\Example 1\venv\lib\site-packages\sqlalchemy\pool\base.py", line 868, in _checkout
    fairy = _ConnectionRecord.checkout(pool)
  File "D:\2. Information Technology\15. Python\7. Learn\3. FastAPi\Example 1\venv\lib\site-packages\sqlalchemy\pool\base.py", line 476, in checkout
    rec = pool._do_get()
  File "D:\2. Information Technology\15. Python\7. Learn\3. FastAPi\Example 1\venv\lib\site-packages\sqlalchemy\pool\impl.py", line 146, in _do_get
    self._dec_overflow()
  File "D:\2. Information Technology\15. Python\7. Learn\3. FastAPi\Example 1\venv\lib\site-packages\sqlalchemy\util\langhelpers.py", line 70, in __exit__
    compat.raise_(
  File "D:\2. Information Technology\15. Python\7. Learn\3. FastAPi\Example 1\venv\lib\site-packages\sqlalchemy\util\compat.py", line 207, in raise_
    raise exception
  File "D:\2. Information Technology\15. Python\7. Learn\3. FastAPi\Example 1\venv\lib\site-packages\sqlalchemy\pool\impl.py", line 143, in _do_get
    return self._create_connection()
  File "D:\2. Information Technology\15. Python\7. Learn\3. FastAPi\Example 1\venv\lib\site-packages\sqlalchemy\pool\base.py", line 256, in _create_connection
    return _ConnectionRecord(self)
  File "D:\2. Information Technology\15. Python\7. Learn\3. FastAPi\Example 1\venv\lib\site-packages\sqlalchemy\pool\base.py", line 371, in __init__
    self.__connect()
  File "D:\2. Information Technology\15. Python\7. Learn\3. FastAPi\Example 1\venv\lib\site-packages\sqlalchemy\pool\base.py", line 666, in __connect
    pool.logger.debug("Error on connect(): %s", e)
  File "D:\2. Information Technology\15. Python\7. Learn\3. FastAPi\Example 1\venv\lib\site-packages\sqlalchemy\util\langhelpers.py", line 70, in __exit__
    compat.raise_(
  File "D:\2. Information Technology\15. Python\7. Learn\3. FastAPi\Example 1\venv\lib\site-packages\sqlalchemy\util\compat.py", line 207, in raise_
    raise exception
  File "D:\2. Information Technology\15. Python\7. Learn\3. FastAPi\Example 1\venv\lib\site-packages\sqlalchemy\pool\base.py", line 661, in __connect
    self.dbapi_connection = connection = pool._invoke_creator(self)
  File "D:\2. Information Technology\15. Python\7. Learn\3. FastAPi\Example 1\venv\lib\site-packages\sqlalchemy\engine\create.py", line 590, in connect
    return dialect.connect(*cargs, **cparams)
  File "D:\2. Information Technology\15. Python\7. Learn\3. FastAPi\Example 1\venv\lib\site-packages\sqlalchemy\engine\default.py", line 597, in connect
    return self.dbapi.connect(*cargs, **cparams)
  File "D:\2. Information Technology\15. Python\7. Learn\3. FastAPi\Example 1\venv\lib\site-packages\psycopg2\__init__.py", line 122, in connect
    conn = _connect(dsn, connection_factory=connection_factory, **kwasync)
psycopg2.OperationalError: connection to server at "localhost" (::1), port 5432 failed: FATAL:  password authentication failed for user "postgres"


The above exception was the direct cause of the following exception:

Traceback (most recent call last):
  File "D:\2. Information Technology\15. Python\7. Learn\3. FastAPi\Example 1\.\api\api_v1\endpoints\student.py", line 33, in get_all_student
    db_obj = crud.student.get_all(db=db)
  File "D:\2. Information Technology\15. Python\7. Learn\3. FastAPi\Example 1\.\crud\crud_student.py", line 14, in get_all
    db_obj = db.query(self.model).all()
  File "D:\2. Information Technology\15. Python\7. Learn\3. FastAPi\Example 1\venv\lib\site-packages\sqlalchemy\orm\query.py", line 2759, in all
    return self._iter().all()
  File "D:\2. Information Technology\15. Python\7. Learn\3. FastAPi\Example 1\venv\lib\site-packages\sqlalchemy\orm\query.py", line 2894, in _iter
    result = self.session.execute(
  File "D:\2. Information Technology\15. Python\7. Learn\3. FastAPi\Example 1\venv\lib\site-packages\sqlalchemy\orm\session.py", line 1691, in execute
    conn = self._connection_for_bind(bind)
  File "D:\2. Information Technology\15. Python\7. Learn\3. FastAPi\Example 1\venv\lib\site-packages\sqlalchemy\orm\session.py", line 1532, in _connection_for_bind
    return self._transaction._connection_for_bind(
  File "D:\2. Information Technology\15. Python\7. Learn\3. FastAPi\Example 1\venv\lib\site-packages\sqlalchemy\orm\session.py", line 747, in _connection_for_bind
    conn = bind.connect()
  File "D:\2. Information Technology\15. Python\7. Learn\3. FastAPi\Example 1\venv\lib\site-packages\sqlalchemy\engine\base.py", line 3204, in connect
    return self._connection_cls(self, close_with_result=close_with_result)
  File "D:\2. Information Technology\15. Python\7. Learn\3. FastAPi\Example 1\venv\lib\site-packages\sqlalchemy\engine\base.py", line 96, in __init__
    else engine.raw_connection()
  File "D:\2. Information Technology\15. Python\7. Learn\3. FastAPi\Example 1\venv\lib\site-packages\sqlalchemy\engine\base.py", line 3283, in raw_connection
    return self._wrap_pool_connect(self.pool.connect, _connection)
  File "D:\2. Information Technology\15. Python\7. Learn\3. FastAPi\Example 1\venv\lib\site-packages\sqlalchemy\engine\base.py", line 3253, in _wrap_pool_connect
    Connection._handle_dbapi_exception_noconnection(
  File "D:\2. Information Technology\15. Python\7. Learn\3. FastAPi\Example 1\venv\lib\site-packages\sqlalchemy\engine\base.py", line 2100, in _handle_dbapi_exception_noconnection
    util.raise_(
  File "D:\2. Information Technology\15. Python\7. Learn\3. FastAPi\Example 1\venv\lib\site-packages\sqlalchemy\util\compat.py", line 207, in raise_
    raise exception
  File "D:\2. Information Technology\15. Python\7. Learn\3. FastAPi\Example 1\venv\lib\site-packages\sqlalchemy\engine\base.py", line 3250, in _wrap_pool_connect
    return fn()
  File "D:\2. Information Technology\15. Python\7. Learn\3. FastAPi\Example 1\venv\lib\site-packages\sqlalchemy\pool\base.py", line 310, in connect
    return _ConnectionFairy._checkout(self)
  File "D:\2. Information Technology\15. Python\7. Learn\3. FastAPi\Example 1\venv\lib\site-packages\sqlalchemy\pool\base.py", line 868, in _checkout
    fairy = _ConnectionRecord.checkout(pool)
  File "D:\2. Information Technology\15. Python\7. Learn\3. FastAPi\Example 1\venv\lib\site-packages\sqlalchemy\pool\base.py", line 476, in checkout
    rec = pool._do_get()
  File "D:\2. Information Technology\15. Python\7. Learn\3. FastAPi\Example 1\venv\lib\site-packages\sqlalchemy\pool\impl.py", line 146, in _do_get
    self._dec_overflow()
  File "D:\2. Information Technology\15. Python\7. Learn\3. FastAPi\Example 1\venv\lib\site-packages\sqlalchemy\util\langhelpers.py", line 70, in __exit__
    compat.raise_(
  File "D:\2. Information Technology\15. Python\7. Learn\3. FastAPi\Example 1\venv\lib\site-packages\sqlalchemy\util\compat.py", line 207, in raise_
    raise exception
  File "D:\2. Information Technology\15. Python\7. Learn\3. FastAPi\Example 1\venv\lib\site-packages\sqlalchemy\pool\impl.py", line 143, in _do_get
    return self._create_connection()
  File "D:\2. Information Technology\15. Python\7. Learn\3. FastAPi\Example 1\venv\lib\site-packages\sqlalchemy\pool\base.py", line 256, in _create_connection
    return _ConnectionRecord(self)
  File "D:\2. Information Technology\15. Python\7. Learn\3. FastAPi\Example 1\venv\lib\site-packages\sqlalchemy\pool\base.py", line 371, in __init__
    self.__connect()
  File "D:\2. Information Technology\15. Python\7. Learn\3. FastAPi\Example 1\venv\lib\site-packages\sqlalchemy\pool\base.py", line 666, in __connect
    pool.logger.debug("Error on connect(): %s", e)
  File "D:\2. Information Technology\15. Python\7. Learn\3. FastAPi\Example 1\venv\lib\site-packages\sqlalchemy\util\langhelpers.py", line 70, in __exit__
    compat.raise_(
  File "D:\2. Information Technology\15. Python\7. Learn\3. FastAPi\Example 1\venv\lib\site-packages\sqlalchemy\util\compat.py", line 207, in raise_
    raise exception
  File "D:\2. Information Technology\15. Python\7. Learn\3. FastAPi\Example 1\venv\lib\site-packages\sqlalchemy\pool\base.py", line 661, in __connect
    self.dbapi_connection = connection = pool._invoke_creator(self)
  File "D:\2. Information Technology\15. Python\7. Learn\3. FastAPi\Example 1\venv\lib\site-packages\sqlalchemy\engine\create.py", line 590, in connect
    return dialect.connect(*cargs, **cparams)
  File "D:\2. Information Technology\15. Python\7. Learn\3. FastAPi\Example 1\venv\lib\site-packages\sqlalchemy\engine\default.py", line 597, in connect
    return self.dbapi.connect(*cargs, **cparams)
  File "D:\2. Information Technology\15. Python\7. Learn\3. FastAPi\Example 1\venv\lib\site-packages\psycopg2\__init__.py", line 122, in connect
    conn = _connect(dsn, connection_factory=connection_factory, **kwasync)
sqlalchemy.exc.OperationalError: (psycopg2.OperationalError) connection to server at "localhost" (::1), port 5432 failed: FATAL:  password authentication failed for user "postgres"

(Background on this error at: https://sqlalche.me/e/14/e3q8)

During handling of the above exception, another exception occurred:

Traceback (most recent call last):
  File "D:\2. Information Technology\15. Python\7. Learn\3. FastAPi\Example 1\venv\lib\site-packages\starlette\exceptions.py", line 71, in __call__
    await self.app(scope, receive, sender)
  File "D:\2. Information Technology\15. Python\7. Learn\3. FastAPi\Example 1\venv\lib\site-packages\starlette\routing.py", line 656, in __call__
    await route.handle(scope, receive, send)
  File "D:\2. Information Technology\15. Python\7. Learn\3. FastAPi\Example 1\venv\lib\site-packages\starlette\routing.py", line 259, in handle
    await self.app(scope, receive, send)
  File "D:\2. Information Technology\15. Python\7. Learn\3. FastAPi\Example 1\venv\lib\site-packages\starlette\routing.py", line 61, in app
    response = await func(request)
  File "D:\2. Information Technology\15. Python\7. Learn\3. FastAPi\Example 1\venv\lib\site-packages\fastapi\routing.py", line 226, in app
    raw_response = await run_endpoint_function(
  File "D:\2. Information Technology\15. Python\7. Learn\3. FastAPi\Example 1\venv\lib\site-packages\fastapi\routing.py", line 161, in run_endpoint_function
    return await run_in_threadpool(dependant.call, **values)
  File "D:\2. Information Technology\15. Python\7. Learn\3. FastAPi\Example 1\venv\lib\site-packages\starlette\concurrency.py", line 39, in run_in_threadpool
    return await anyio.to_thread.run_sync(func, *args)
  File "D:\2. Information Technology\15. Python\7. Learn\3. FastAPi\Example 1\venv\lib\site-packages\anyio\to_thread.py", line 28, in run_sync
    return await get_asynclib().run_sync_in_worker_thread(func, *args, cancellable=cancellable,
  File "D:\2. Information Technology\15. Python\7. Learn\3. FastAPi\Example 1\venv\lib\site-packages\anyio\_backends\_asyncio.py", line 818, in run_sync_in_worker_thread
    return await future
  File "D:\2. Information Technology\15. Python\7. Learn\3. FastAPi\Example 1\venv\lib\site-packages\anyio\_backends\_asyncio.py", line 754, in run
    result = context.run(func, *args)
  File "D:\2. Information Technology\15. Python\7. Learn\3. FastAPi\Example 1\.\api\api_v1\endpoints\student.py", line 35, in get_all_student
    raise HTTPException(status_code=status.HTTP_500_INTERNAL_SERVER_ERROR,
fastapi.exceptions.HTTPException

During handling of the above exception, another exception occurred:

Traceback (most recent call last):
  File "D:\2. Information Technology\15. Python\7. Learn\3. FastAPi\Example 1\venv\lib\site-packages\uvicorn\protocols\http\httptools_impl.py", line 375, in run_asgi
    result = await app(self.scope, self.receive, self.send)
  File "D:\2. Information Technology\15. Python\7. Learn\3. FastAPi\Example 1\venv\lib\site-packages\uvicorn\middleware\proxy_headers.py", line 75, in __call__
    return await self.app(scope, receive, send)
  File "D:\2. Information Technology\15. Python\7. Learn\3. FastAPi\Example 1\venv\lib\site-packages\fastapi\applications.py", line 208, in __call__
    await super().__call__(scope, receive, send)
  File "D:\2. Information Technology\15. Python\7. Learn\3. FastAPi\Example 1\venv\lib\site-packages\starlette\applications.py", line 112, in __call__
    await self.middleware_stack(scope, receive, send)
  File "D:\2. Information Technology\15. Python\7. Learn\3. FastAPi\Example 1\venv\lib\site-packages\starlette\middleware\errors.py", line 181, in __call__
    raise exc
  File "D:\2. Information Technology\15. Python\7. Learn\3. FastAPi\Example 1\venv\lib\site-packages\starlette\middleware\errors.py", line 159, in __call__
    await self.app(scope, receive, _send)
  File "D:\2. Information Technology\15. Python\7. Learn\3. FastAPi\Example 1\venv\lib\site-packages\starlette\exceptions.py", line 90, in __call__
    response = await handler(request, exc)
  File "D:\2. Information Technology\15. Python\7. Learn\3. FastAPi\Example 1\venv\lib\site-packages\fastapi\exception_handlers.py", line 16, in http_exception_handler
    return JSONResponse({"detail": exc.detail}, status_code=exc.status_code)
  File "D:\2. Information Technology\15. Python\7. Learn\3. FastAPi\Example 1\venv\lib\site-packages\starlette\responses.py", line 49, in __init__
    self.body = self.render(content)
  File "D:\2. Information Technology\15. Python\7. Learn\3. FastAPi\Example 1\venv\lib\site-packages\starlette\responses.py", line 157, in render
    return json.dumps(
  File "C:\Users\MINH\AppData\Local\Programs\Python\Python39\lib\json\__init__.py", line 234, in dumps
    return cls(
  File "C:\Users\MINH\AppData\Local\Programs\Python\Python39\lib\json\encoder.py", line 199, in encode
    chunks = self.iterencode(o, _one_shot=True)
  File "C:\Users\MINH\AppData\Local\Programs\Python\Python39\lib\json\encoder.py", line 257, in iterencode
    return _iterencode(o, 0)
  File "C:\Users\MINH\AppData\Local\Programs\Python\Python39\lib\json\encoder.py", line 179, in default
    raise TypeError(f'Object of type {o.__class__.__name__} '
TypeError: Object of type OperationalError is not JSON serializable
ERROR:uvicorn.error:Exception in ASGI application
Traceback (most recent call last):
  File "D:\2. Information Technology\15. Python\7. Learn\3. FastAPi\Example 1\venv\lib\site-packages\sqlalchemy\engine\base.py", line 3250, in _wrap_pool_connect
    return fn()
  File "D:\2. Information Technology\15. Python\7. Learn\3. FastAPi\Example 1\venv\lib\site-packages\sqlalchemy\pool\base.py", line 310, in connect
    return _ConnectionFairy._checkout(self)
  File "D:\2. Information Technology\15. Python\7. Learn\3. FastAPi\Example 1\venv\lib\site-packages\sqlalchemy\pool\base.py", line 868, in _checkout
    fairy = _ConnectionRecord.checkout(pool)
  File "D:\2. Information Technology\15. Python\7. Learn\3. FastAPi\Example 1\venv\lib\site-packages\sqlalchemy\pool\base.py", line 476, in checkout
    rec = pool._do_get()
  File "D:\2. Information Technology\15. Python\7. Learn\3. FastAPi\Example 1\venv\lib\site-packages\sqlalchemy\pool\impl.py", line 146, in _do_get
    self._dec_overflow()
  File "D:\2. Information Technology\15. Python\7. Learn\3. FastAPi\Example 1\venv\lib\site-packages\sqlalchemy\util\langhelpers.py", line 70, in __exit__
    compat.raise_(
  File "D:\2. Information Technology\15. Python\7. Learn\3. FastAPi\Example 1\venv\lib\site-packages\sqlalchemy\util\compat.py", line 207, in raise_
    raise exception
  File "D:\2. Information Technology\15. Python\7. Learn\3. FastAPi\Example 1\venv\lib\site-packages\sqlalchemy\pool\impl.py", line 143, in _do_get
    return self._create_connection()
  File "D:\2. Information Technology\15. Python\7. Learn\3. FastAPi\Example 1\venv\lib\site-packages\sqlalchemy\pool\base.py", line 256, in _create_connection
    return _ConnectionRecord(self)
  File "D:\2. Information Technology\15. Python\7. Learn\3. FastAPi\Example 1\venv\lib\site-packages\sqlalchemy\pool\base.py", line 371, in __init__
    self.__connect()
  File "D:\2. Information Technology\15. Python\7. Learn\3. FastAPi\Example 1\venv\lib\site-packages\sqlalchemy\pool\base.py", line 666, in __connect
    pool.logger.debug("Error on connect(): %s", e)
  File "D:\2. Information Technology\15. Python\7. Learn\3. FastAPi\Example 1\venv\lib\site-packages\sqlalchemy\util\langhelpers.py", line 70, in __exit__
    compat.raise_(
  File "D:\2. Information Technology\15. Python\7. Learn\3. FastAPi\Example 1\venv\lib\site-packages\sqlalchemy\util\compat.py", line 207, in raise_
    raise exception
  File "D:\2. Information Technology\15. Python\7. Learn\3. FastAPi\Example 1\venv\lib\site-packages\sqlalchemy\pool\base.py", line 661, in __connect
    self.dbapi_connection = connection = pool._invoke_creator(self)
  File "D:\2. Information Technology\15. Python\7. Learn\3. FastAPi\Example 1\venv\lib\site-packages\sqlalchemy\engine\create.py", line 590, in connect
    return dialect.connect(*cargs, **cparams)
  File "D:\2. Information Technology\15. Python\7. Learn\3. FastAPi\Example 1\venv\lib\site-packages\sqlalchemy\engine\default.py", line 597, in connect
    return self.dbapi.connect(*cargs, **cparams)
  File "D:\2. Information Technology\15. Python\7. Learn\3. FastAPi\Example 1\venv\lib\site-packages\psycopg2\__init__.py", line 122, in connect
    conn = _connect(dsn, connection_factory=connection_factory, **kwasync)
psycopg2.OperationalError: connection to server at "localhost" (::1), port 5432 failed: FATAL:  password authentication failed for user "postgres"


The above exception was the direct cause of the following exception:

Traceback (most recent call last):
  File "D:\2. Information Technology\15. Python\7. Learn\3. FastAPi\Example 1\.\api\api_v1\endpoints\student.py", line 33, in get_all_student
    db_obj = crud.student.get_all(db=db)
  File "D:\2. Information Technology\15. Python\7. Learn\3. FastAPi\Example 1\.\crud\crud_student.py", line 14, in get_all
    db_obj = db.query(self.model).all()
  File "D:\2. Information Technology\15. Python\7. Learn\3. FastAPi\Example 1\venv\lib\site-packages\sqlalchemy\orm\query.py", line 2759, in all
    return self._iter().all()
  File "D:\2. Information Technology\15. Python\7. Learn\3. FastAPi\Example 1\venv\lib\site-packages\sqlalchemy\orm\query.py", line 2894, in _iter
    result = self.session.execute(
  File "D:\2. Information Technology\15. Python\7. Learn\3. FastAPi\Example 1\venv\lib\site-packages\sqlalchemy\orm\session.py", line 1691, in execute
    conn = self._connection_for_bind(bind)
  File "D:\2. Information Technology\15. Python\7. Learn\3. FastAPi\Example 1\venv\lib\site-packages\sqlalchemy\orm\session.py", line 1532, in _connection_for_bind
    return self._transaction._connection_for_bind(
  File "D:\2. Information Technology\15. Python\7. Learn\3. FastAPi\Example 1\venv\lib\site-packages\sqlalchemy\orm\session.py", line 747, in _connection_for_bind
    conn = bind.connect()
  File "D:\2. Information Technology\15. Python\7. Learn\3. FastAPi\Example 1\venv\lib\site-packages\sqlalchemy\engine\base.py", line 3204, in connect
    return self._connection_cls(self, close_with_result=close_with_result)
  File "D:\2. Information Technology\15. Python\7. Learn\3. FastAPi\Example 1\venv\lib\site-packages\sqlalchemy\engine\base.py", line 96, in __init__
    else engine.raw_connection()
  File "D:\2. Information Technology\15. Python\7. Learn\3. FastAPi\Example 1\venv\lib\site-packages\sqlalchemy\engine\base.py", line 3283, in raw_connection
    return self._wrap_pool_connect(self.pool.connect, _connection)
  File "D:\2. Information Technology\15. Python\7. Learn\3. FastAPi\Example 1\venv\lib\site-packages\sqlalchemy\engine\base.py", line 3253, in _wrap_pool_connect
    Connection._handle_dbapi_exception_noconnection(
  File "D:\2. Information Technology\15. Python\7. Learn\3. FastAPi\Example 1\venv\lib\site-packages\sqlalchemy\engine\base.py", line 2100, in _handle_dbapi_exception_noconnection
    util.raise_(
  File "D:\2. Information Technology\15. Python\7. Learn\3. FastAPi\Example 1\venv\lib\site-packages\sqlalchemy\util\compat.py", line 207, in raise_
    raise exception
  File "D:\2. Information Technology\15. Python\7. Learn\3. FastAPi\Example 1\venv\lib\site-packages\sqlalchemy\engine\base.py", line 3250, in _wrap_pool_connect
    return fn()
  File "D:\2. Information Technology\15. Python\7. Learn\3. FastAPi\Example 1\venv\lib\site-packages\sqlalchemy\pool\base.py", line 310, in connect
    return _ConnectionFairy._checkout(self)
  File "D:\2. Information Technology\15. Python\7. Learn\3. FastAPi\Example 1\venv\lib\site-packages\sqlalchemy\pool\base.py", line 868, in _checkout
    fairy = _ConnectionRecord.checkout(pool)
  File "D:\2. Information Technology\15. Python\7. Learn\3. FastAPi\Example 1\venv\lib\site-packages\sqlalchemy\pool\base.py", line 476, in checkout
    rec = pool._do_get()
  File "D:\2. Information Technology\15. Python\7. Learn\3. FastAPi\Example 1\venv\lib\site-packages\sqlalchemy\pool\impl.py", line 146, in _do_get
    self._dec_overflow()
  File "D:\2. Information Technology\15. Python\7. Learn\3. FastAPi\Example 1\venv\lib\site-packages\sqlalchemy\util\langhelpers.py", line 70, in __exit__
    compat.raise_(
  File "D:\2. Information Technology\15. Python\7. Learn\3. FastAPi\Example 1\venv\lib\site-packages\sqlalchemy\util\compat.py", line 207, in raise_
    raise exception
  File "D:\2. Information Technology\15. Python\7. Learn\3. FastAPi\Example 1\venv\lib\site-packages\sqlalchemy\pool\impl.py", line 143, in _do_get
    return self._create_connection()
  File "D:\2. Information Technology\15. Python\7. Learn\3. FastAPi\Example 1\venv\lib\site-packages\sqlalchemy\pool\base.py", line 256, in _create_connection
    return _ConnectionRecord(self)
  File "D:\2. Information Technology\15. Python\7. Learn\3. FastAPi\Example 1\venv\lib\site-packages\sqlalchemy\pool\base.py", line 371, in __init__
    self.__connect()
  File "D:\2. Information Technology\15. Python\7. Learn\3. FastAPi\Example 1\venv\lib\site-packages\sqlalchemy\pool\base.py", line 666, in __connect
    pool.logger.debug("Error on connect(): %s", e)
  File "D:\2. Information Technology\15. Python\7. Learn\3. FastAPi\Example 1\venv\lib\site-packages\sqlalchemy\util\langhelpers.py", line 70, in __exit__
    compat.raise_(
  File "D:\2. Information Technology\15. Python\7. Learn\3. FastAPi\Example 1\venv\lib\site-packages\sqlalchemy\util\compat.py", line 207, in raise_
    raise exception
  File "D:\2. Information Technology\15. Python\7. Learn\3. FastAPi\Example 1\venv\lib\site-packages\sqlalchemy\pool\base.py", line 661, in __connect
    self.dbapi_connection = connection = pool._invoke_creator(self)
  File "D:\2. Information Technology\15. Python\7. Learn\3. FastAPi\Example 1\venv\lib\site-packages\sqlalchemy\engine\create.py", line 590, in connect
    return dialect.connect(*cargs, **cparams)
  File "D:\2. Information Technology\15. Python\7. Learn\3. FastAPi\Example 1\venv\lib\site-packages\sqlalchemy\engine\default.py", line 597, in connect
    return self.dbapi.connect(*cargs, **cparams)
  File "D:\2. Information Technology\15. Python\7. Learn\3. FastAPi\Example 1\venv\lib\site-packages\psycopg2\__init__.py", line 122, in connect
    conn = _connect(dsn, connection_factory=connection_factory, **kwasync)
sqlalchemy.exc.OperationalError: (psycopg2.OperationalError) connection to server at "localhost" (::1), port 5432 failed: FATAL:  password authentication failed for user "postgres"

(Background on this error at: https://sqlalche.me/e/14/e3q8)

During handling of the above exception, another exception occurred:

Traceback (most recent call last):
  File "D:\2. Information Technology\15. Python\7. Learn\3. FastAPi\Example 1\venv\lib\site-packages\starlette\exceptions.py", line 71, in __call__
    await self.app(scope, receive, sender)
  File "D:\2. Information Technology\15. Python\7. Learn\3. FastAPi\Example 1\venv\lib\site-packages\starlette\routing.py", line 656, in __call__
    await route.handle(scope, receive, send)
  File "D:\2. Information Technology\15. Python\7. Learn\3. FastAPi\Example 1\venv\lib\site-packages\starlette\routing.py", line 259, in handle
    await self.app(scope, receive, send)
  File "D:\2. Information Technology\15. Python\7. Learn\3. FastAPi\Example 1\venv\lib\site-packages\starlette\routing.py", line 61, in app
    response = await func(request)
  File "D:\2. Information Technology\15. Python\7. Learn\3. FastAPi\Example 1\venv\lib\site-packages\fastapi\routing.py", line 226, in app
    raw_response = await run_endpoint_function(
  File "D:\2. Information Technology\15. Python\7. Learn\3. FastAPi\Example 1\venv\lib\site-packages\fastapi\routing.py", line 161, in run_endpoint_function
    return await run_in_threadpool(dependant.call, **values)
  File "D:\2. Information Technology\15. Python\7. Learn\3. FastAPi\Example 1\venv\lib\site-packages\starlette\concurrency.py", line 39, in run_in_threadpool
    return await anyio.to_thread.run_sync(func, *args)
  File "D:\2. Information Technology\15. Python\7. Learn\3. FastAPi\Example 1\venv\lib\site-packages\anyio\to_thread.py", line 28, in run_sync
    return await get_asynclib().run_sync_in_worker_thread(func, *args, cancellable=cancellable,
  File "D:\2. Information Technology\15. Python\7. Learn\3. FastAPi\Example 1\venv\lib\site-packages\anyio\_backends\_asyncio.py", line 818, in run_sync_in_worker_thread
    return await future
  File "D:\2. Information Technology\15. Python\7. Learn\3. FastAPi\Example 1\venv\lib\site-packages\anyio\_backends\_asyncio.py", line 754, in run
    result = context.run(func, *args)
  File "D:\2. Information Technology\15. Python\7. Learn\3. FastAPi\Example 1\.\api\api_v1\endpoints\student.py", line 35, in get_all_student
    raise HTTPException(status_code=status.HTTP_500_INTERNAL_SERVER_ERROR,
fastapi.exceptions.HTTPException

During handling of the above exception, another exception occurred:

Traceback (most recent call last):
  File "D:\2. Information Technology\15. Python\7. Learn\3. FastAPi\Example 1\venv\lib\site-packages\uvicorn\protocols\http\httptools_impl.py", line 375, in run_asgi
    result = await app(self.scope, self.receive, self.send)
  File "D:\2. Information Technology\15. Python\7. Learn\3. FastAPi\Example 1\venv\lib\site-packages\uvicorn\middleware\proxy_headers.py", line 75, in __call__
    return await self.app(scope, receive, send)
  File "D:\2. Information Technology\15. Python\7. Learn\3. FastAPi\Example 1\venv\lib\site-packages\fastapi\applications.py", line 208, in __call__
    await super().__call__(scope, receive, send)
  File "D:\2. Information Technology\15. Python\7. Learn\3. FastAPi\Example 1\venv\lib\site-packages\starlette\applications.py", line 112, in __call__
    await self.middleware_stack(scope, receive, send)
  File "D:\2. Information Technology\15. Python\7. Learn\3. FastAPi\Example 1\venv\lib\site-packages\starlette\middleware\errors.py", line 181, in __call__
    raise exc
  File "D:\2. Information Technology\15. Python\7. Learn\3. FastAPi\Example 1\venv\lib\site-packages\starlette\middleware\errors.py", line 159, in __call__
    await self.app(scope, receive, _send)
  File "D:\2. Information Technology\15. Python\7. Learn\3. FastAPi\Example 1\venv\lib\site-packages\starlette\exceptions.py", line 90, in __call__
    response = await handler(request, exc)
  File "D:\2. Information Technology\15. Python\7. Learn\3. FastAPi\Example 1\venv\lib\site-packages\fastapi\exception_handlers.py", line 16, in http_exception_handler
    return JSONResponse({"detail": exc.detail}, status_code=exc.status_code)
  File "D:\2. Information Technology\15. Python\7. Learn\3. FastAPi\Example 1\venv\lib\site-packages\starlette\responses.py", line 49, in __init__
    self.body = self.render(content)
  File "D:\2. Information Technology\15. Python\7. Learn\3. FastAPi\Example 1\venv\lib\site-packages\starlette\responses.py", line 157, in render
    return json.dumps(
  File "C:\Users\MINH\AppData\Local\Programs\Python\Python39\lib\json\__init__.py", line 234, in dumps
    return cls(
  File "C:\Users\MINH\AppData\Local\Programs\Python\Python39\lib\json\encoder.py", line 199, in encode
    chunks = self.iterencode(o, _one_shot=True)
  File "C:\Users\MINH\AppData\Local\Programs\Python\Python39\lib\json\encoder.py", line 257, in iterencode
    return _iterencode(o, 0)
  File "C:\Users\MINH\AppData\Local\Programs\Python\Python39\lib\json\encoder.py", line 179, in default
    raise TypeError(f'Object of type {o.__class__.__name__} '
TypeError: Object of type OperationalError is not JSON serializable
INFO:uvicorn.error:Shutting down
INFO:uvicorn.error:Started server process [8004]
INFO:uvicorn.error:Waiting for application startup.
INFO:uvicorn.error:Application startup complete.
INFO:uvicorn.error:Started server process [3540]
INFO:uvicorn.error:Waiting for application startup.
INFO:uvicorn.error:Application startup complete.
INFO:uvicorn.error:Shutting down
